INFO 2025-09-05 17:39:29,039 [main.py (startup)] BOT STARTED
INFO 2025-09-05 17:39:50,163 [log.py (__call__)] USER 2054556183~shayZi12345 ROUTER slash_commands_user_router CALLBACK start
ERROR 2025-09-05 17:39:51,769 [user.py (__call__)] Middleware get user error 500 Произошла ошибка. Повторите попытку позже.
INFO 2025-09-05 17:41:48,150 [main.py (startup)] BOT STARTED
INFO 2025-09-05 17:41:55,132 [log.py (__call__)] USER 2054556183~shayZi12345 ROUTER slash_commands_user_router CALLBACK start
INFO 2025-09-05 17:41:55,924 [user.py (__call__)] New user in bot 2054556183 shayZi12345
ERROR 2025-09-05 17:41:55,926 [log.py (__call__)] Message.answer() missing 1 required positional argument: 'text'
Traceback (most recent call last):
  File "C:\Users\dyadh\OneDrive\Рабочий стол\FastFy\bot\bot\middleware\log.py", line 29, in __call__
    return await handler(event, data)
  File "C:\Users\dyadh\OneDrive\Рабочий стол\FastFy\bot\bot\middleware\user.py", line 52, in __call__
    await answer_event.answer(
TypeError: Message.answer() missing 1 required positional argument: 'text'
INFO 2025-09-05 17:42:59,705 [main.py (startup)] BOT STARTED
INFO 2025-09-05 17:43:06,090 [log.py (__call__)] USER 2054556183~shayZi12345 ROUTER slash_commands_user_router CALLBACK start
INFO 2025-09-05 17:43:06,600 [user.py (__call__)] New user in bot 2054556183 shayZi12345
INFO 2025-09-05 17:44:33,319 [log.py (__call__)] USER 2054556183~shayZi12345 ROUTER state_user_router CALLBACK login_state_code
INFO 2025-09-05 17:44:51,650 [log.py (__call__)] USER 2054556183~shayZi12345 ROUTER slash_commands_user_router CALLBACK account
INFO 2025-09-05 17:46:02,909 [log.py (__call__)] USER 2054556183~shayZi12345 ROUTER slash_commands_user_router CALLBACK start
INFO 2025-09-05 17:46:05,312 [log.py (__call__)] USER 2054556183~shayZi12345 ROUTER slash_commands_user_router CALLBACK start
INFO 2025-09-05 17:46:52,677 [log.py (__call__)] USER 2054556183~shayZi12345 ROUTER slash_commands_user_router CALLBACK clear
INFO 2025-09-05 17:53:00,426 [main.py (startup)] BOT STARTED
INFO 2025-09-05 17:53:16,261 [log.py (__call__)] USER 2054556183~shayZi12345 ROUTER slash_commands_user_router CALLBACK profile
ERROR 2025-09-05 17:53:17,211 [log.py (__call__)] 'UserSchema' object has no attribute 'profile_text'
Traceback (most recent call last):
  File "C:\Users\dyadh\OneDrive\Рабочий стол\FastFy\bot\bot\middleware\log.py", line 29, in __call__
    return await handler(event, data)
  File "C:\Users\dyadh\OneDrive\Рабочий стол\FastFy\bot\bot\middleware\user.py", line 64, in __call__
    return await handler(event, data)
  File "C:\Users\dyadh\OneDrive\Рабочий стол\FastFy\venv\lib\site-packages\aiogram_tool\depend\components\inner_middleware.py", line 42, in __call__
    return await handler(event, data)
  File "C:\Users\dyadh\OneDrive\Рабочий стол\FastFy\venv\lib\site-packages\aiogram\dispatcher\event\handler.py", line 43, in call
    return await wrapped()
  File "C:\Users\dyadh\OneDrive\Рабочий стол\FastFy\bot\bot\handlers\slash_commands\user\router.py", line 44, in profile
    caption=user.profile_text(),
  File "C:\Users\dyadh\OneDrive\Рабочий стол\FastFy\venv\lib\site-packages\pydantic\main.py", line 991, in __getattr__
    raise AttributeError(f'{type(self).__name__!r} object has no attribute {item!r}')
AttributeError: 'UserSchema' object has no attribute 'profile_text'
INFO 2025-09-05 17:53:52,532 [main.py (shutdown)] BOT SHUTDOWN
INFO 2025-09-05 17:53:57,083 [main.py (startup)] BOT STARTED
INFO 2025-09-05 17:54:10,083 [log.py (__call__)] USER 2054556183~shayZi12345 ROUTER slash_commands_user_router CALLBACK profile
ERROR 2025-09-05 17:54:10,816 [log.py (__call__)] 1 validation error for SendPhoto
caption
  Input should be a valid string [type=string_type, input_value=('Steam ID: 7656119920798...45\nПроцент: 10'), input_type=tuple]
    For further information visit https://errors.pydantic.dev/2.11/v/string_type
Traceback (most recent call last):
  File "C:\Users\dyadh\OneDrive\Рабочий стол\FastFy\bot\bot\middleware\log.py", line 29, in __call__
    return await handler(event, data)
  File "C:\Users\dyadh\OneDrive\Рабочий стол\FastFy\bot\bot\middleware\user.py", line 64, in __call__
    return await handler(event, data)
  File "C:\Users\dyadh\OneDrive\Рабочий стол\FastFy\venv\lib\site-packages\aiogram_tool\depend\components\inner_middleware.py", line 42, in __call__
    return await handler(event, data)
  File "C:\Users\dyadh\OneDrive\Рабочий стол\FastFy\venv\lib\site-packages\aiogram\dispatcher\event\handler.py", line 43, in call
    return await wrapped()
  File "C:\Users\dyadh\OneDrive\Рабочий стол\FastFy\bot\bot\handlers\slash_commands\user\router.py", line 42, in profile
    await message.answer_photo(
  File "C:\Users\dyadh\OneDrive\Рабочий стол\FastFy\venv\lib\site-packages\aiogram\types\message.py", line 2407, in answer_photo
    return SendPhoto(
  File "C:\Users\dyadh\OneDrive\Рабочий стол\FastFy\venv\lib\site-packages\pydantic\main.py", line 253, in __init__
    validated_self = self.__pydantic_validator__.validate_python(data, self_instance=self)
pydantic_core._pydantic_core.ValidationError: 1 validation error for SendPhoto
caption
  Input should be a valid string [type=string_type, input_value=('Steam ID: 7656119920798...45\nПроцент: 10'), input_type=tuple]
    For further information visit https://errors.pydantic.dev/2.11/v/string_type
INFO 2025-09-05 17:54:34,924 [main.py (shutdown)] BOT SHUTDOWN
INFO 2025-09-05 17:54:39,095 [main.py (startup)] BOT STARTED
INFO 2025-09-05 17:54:48,139 [log.py (__call__)] USER 2054556183~shayZi12345 ROUTER slash_commands_user_router CALLBACK profile
INFO 2025-09-05 17:54:51,912 [log.py (__call__)] USER 2054556183~shayZi12345 ROUTER slash_commands_user_router CALLBACK profile
INFO 2025-09-05 17:55:02,691 [log.py (__call__)] USER 2054556183~shayZi12345 ROUTER user_callback_router CALLBACK change_percent_user
INFO 2025-09-05 17:55:07,371 [log.py (__call__)] USER 2054556183~shayZi12345 ROUTER state_user_router CALLBACK user_change_percent
INFO 2025-09-05 17:55:09,683 [log.py (__call__)] USER 2054556183~shayZi12345 ROUTER state_user_router CALLBACK user_change_percent
INFO 2025-09-05 17:55:12,122 [log.py (__call__)] USER 2054556183~shayZi12345 ROUTER state_user_router CALLBACK user_change_percent
INFO 2025-09-05 17:55:16,693 [log.py (__call__)] USER 2054556183~shayZi12345 ROUTER state_user_router CALLBACK user_change_percent
INFO 2025-09-05 17:55:22,213 [log.py (__call__)] USER 2054556183~shayZi12345 ROUTER slash_commands_user_router CALLBACK profile
INFO 2025-09-05 17:55:40,023 [log.py (__call__)] USER 2054556183~shayZi12345 ROUTER slash_commands_user_router CALLBACK profile
INFO 2025-09-05 17:56:00,223 [log.py (__call__)] USER 2054556183~shayZi12345 ROUTER slash_commands_user_router CALLBACK profile
INFO 2025-09-05 17:56:04,934 [log.py (__call__)] USER 2054556183~shayZi12345 ROUTER slash_commands_user_router CALLBACK profile
INFO 2025-09-05 17:57:35,620 [log.py (__call__)] USER 2054556183~shayZi12345 ROUTER user_callback_router CALLBACK change_percent_user
INFO 2025-09-05 17:57:38,819 [log.py (__call__)] USER 2054556183~shayZi12345 ROUTER state_user_router CALLBACK user_change_percent
INFO 2025-09-05 18:01:17,841 [main.py (shutdown)] BOT SHUTDOWN
INFO 2025-09-05 23:48:55,414 [main.py (startup)] BOT STARTED
INFO 2025-09-05 23:49:06,893 [log.py (__call__)] USER 2054556183~shayZi12345 ROUTER slash_commands_user_router CALLBACK search
INFO 2025-09-05 23:49:15,358 [log.py (__call__)] USER 2054556183~shayZi12345 ROUTER slash_commands_user_router CALLBACK clear
INFO 2025-09-05 23:49:18,277 [log.py (__call__)] USER 2054556183~shayZi12345 ROUTER slash_commands_user_router CALLBACK search
INFO 2025-09-05 23:49:25,496 [log.py (__call__)] USER 2054556183~shayZi12345 ROUTER state_user_router CALLBACK skins_search
